Workbook

Sheet Handleiding
A1: Tabblad deelnemers
A2: Bij aanvang invullen de licht grijze velden: | D2: Niet vergeten!! | E2: Dit Excel blad opsturen naar: | H2: mh-support@handboogsport.nl
E3: zodat we de uitslag kunnen publiceren op MijnHandboogsport.
A5: 1e baan nummer (veld D4) (zie hieronder de verklaring)
B6: Indien er gelijktijdig meerdere boogsoorten of klassen wordt verschoten dan worden er meerdere downloads vanuit MijnHandboogsport gedaan. Deze hebben dan alle correcte info in de naam en in het sheet.
B7: Indien er één boogsoort en klasse wordt verschoten 1e baan invullen als 1, als dit de 1e baan van je indeling is.
B8: Voor de 2e boogsoort of klasse op tabblad deelnemers het veld achter 1e baan, cel D4, aanpassen naar het baannummer waarop het eerste team van die boogsoort of klasse staat, bijvoorbeeld 9.
A10: Aantal Aangemelde teams: cel D5, keuze 2, 3 of 4, 5 of 6, 7 of 8, bepaald het schema. Bij 3 of 4 deelnemende teams schiet men een dubbele ronde, en bij 2 teams schiet men 4 rondes. Zie ook regel 38 en 39
A11: LET OP: bij afmeldingen vooraf kun je dit aanpassen maar dan moet je ook alle sheets opnieuw afdrukken. Bij een no-show het betreffende team gewoon laten staan, of in het sheet de naam in een bye veranderen en de rest laten zo als het is.
A12: Bij een no-show waarbij het aantal teams voor de indeling, cel D5, niet veranderd, kun je de naam veranderen in een Bye. Je hoeft dan niets opnieuw te printen en kan gewoon volgens het bestaande schema schieten.
A13: Bij een no-show waarbij het aantal teams voor de indeling, cel D5, WEL veranderd, moet je het team verwijderen en ervoor zorgen dat de deelnemende teams aan een gesloten in de lijst staan, dus geen lege teams tussen deelnemende teams.
A14: Vervolgens pas je veld D5, aangemelde teams aan naar de nieuwe indeling en print je de benodigde formulieren opnieuw. Dit moet omdat het schema van schieten hierdoor veranderd.
A16: tbv deelnemers achter de volgende omschrijving, indien nioet al automatisch gevuld
A17: Baan 1 | B17: Naam Team | C17: Verenigingsnummer | D17: Team info is op voorhand in te vullen n.a.v. de gegevens die van de bond zijn aangeleverd
A18: Schutter 1 | B18: Naam schutter 1 | C18: Bondsnummer | D18: Schutters info invullen door de teams het Naambriefje in te laten vullen. Zie tabblad Naambriefje, selecteer de betreffende baan van het bovenste team , print het formulier, snijd of knip het in 2-en, en deel het uit. Dit is vooral handig bij wijziging van teamleden.
A19: Schutter 2 | B19: Naam schutter 2 | C19: Bondsnummer
A20: Schutter 3 | B20: Naam schutter 3 | C20: Bondsnummer
A22: Als de namen ingevuld zijn verschijnt er automatisch in het vak wedstrijden wie tegen wie schiet in welke ronde
A23: Via het tabblad wedstrijdschema kun je nu ook een overzicht printen wie in welke ronde tegen wie schiet
A24: Op ditzelfde overzicht staan ook eventueel kleuren welke per ronde boven de betreffende baan gehangen kunnen worden. Zorg voor papier rood, blauw, groen en geel.
A25: Deze gekleurde vellen boven de baan kunnen duidelijk maken wie er tegen wie schiet.
A27: Hierna kan men naar het betreffende tabblad Score briefjes (indoor of 25M1P)
A28: Vul in ronde 1 (veld Y2) en print 2 exemplaren van de betreffende scorebriefjes
A29: Vul in ronde 2 (veld Y2) en print 2 exemplaren van de betreffende scorebriefjes
A30: Vul in ronde 3 (veld Y2) en print 2 exemplaren van de betreffende scorebriefjes
A31: idem voor ronde 4, 5, 6 en 7
A32: Bij 3 of 4 deelnemende teams alleen ronde 1, 2 en 3 invullen, en dan 2 keer pagina 1 printen voor een dubbele ronde
A33: Bij 2 deelnemende teams alleen ronde 1 invullen en pagina 1 dan 4 keer printen voor een 4 dubbele ronde
A35: Tabblad scores:
... A47: Als er een foutmelding staat op het tabblad stand dan moet waarschijnlijk er nog een shoot-off ingevuld worden. Zie regel 47-48-49

Sheet Toegestane deelnemers
B1: RK Teams Rayon 4, 25m 1pijl competitie 2025/2026, Recurve klasse D
D6: Alleen onderstaande sporters mogen invallen in dit RK
D7: - Ze hebben genoeg scores neergezet in de regiocompetitie
D8: - Ze hebben een toestaan boogtype voor deze team wedstrijdklasse
D10: Controleer dat de invaller geen hoger gemiddelde heeft
D11: Controleer dat ze met hetzelfde type boog gaan schieten als hier genoemd
D12: Controleer dat ze voor hun eigen vereniging invallen
D13: Kopieer naam en bondsnummer naar het blad Deelnemers
C16: Regio | D16: Vereniging | E16: Sporter | F16: Bondsnummer | G16: Gemiddelde | H16: Boog type | I16: Notitie
C18: 114 | D18: [1164] De Indianen | E18: Wilbert Theeuwen | F18: 108180 | G18: 8,827 | H18: Recurve
E19: Frank Verdonschot | F19: 150921 | G19: 8,733 | H19: Recurve
E20: Bram Kerkhof | F20: 139117 | G20: 8,033 | H20: Recurve
E21: Jori van der Velden | F21: 142672 | G21: 7,927 | H21: Recurve
E22: Ron Smets | F22: 165741 | G22: 7,407 | H22: Recurve
E23: Laura Joosten | F23: 183281 | G23: 7,313 | H23: Recurve
E24: Peter Lenders | F24: 182097 | G24: 6,827 | H24: Recurve
E25: Wiel Theeuwen | F25: 104734 | G25: 5,153 | H25: Recurve
C27: 115 | D27: [1400] HBS De Ster 2.0 | E27: Yael Smeets | F27: 168102 | G27: 9,713 | H27: Recurve
E28: Frank Baets | F28: 139838 | G28: 9,487 | H28: Recurve
E29: Martin Veenman | F29: 175596 | G29: 9,180 | H29: Recurve
E30: Sharon Baets-van der Heijden | F30: 151086 | G30: 9,160 | H30: Recurve
E31: Dari Verwers | F31: 159428 | G31: 9,113 | H31: Recurve
E32: Axel Janssen | F32: 132134 | G32: 8,907 | H32: Recurve
E33: Hennie van der Weijden | F33: 182208 | G33: 8,780 | H33: Recurve
E34: Huub Holtkamp | F34: 180100 | G34: 7,340 | H34: Traditional
E35: Hans Beckers | F35: 183776 | G35: 7,200 | H35: Recurve
E36: Archibald Johnson | F36: 183914 | G36: 6,920 | H36: Recurve
E37: Quinn Vlieks | F37: 157270 | G37: 6,787 | H37: Barebow
E38: Jean Smeets | F38: 165744 | G38: 6,540 | H38: Recurve
E39: Omayma Saïdi | F39: 180820 | G39: 6,380 | H39: Recurve
... E42: Harrie Vroomen | F42: 165359 | G42: 5,367 | H42: Longbow
B44: Deze gegevens zijn opgehaald op 2026-03-17 21:20:36

Sheet Deelnemers
B1: RK Teams Rayon 4, 25m 1pijl competitie 2025/2026
A2: Klasse | B2: Recurve klasse D
A3: Organisator | B3: Willem Tell 1921, Kerkrade
A4: Datum | B4: 2026-04-11 | C4: 1e baan: | D4: 1
B5: Aantal aangemelde teams: | D5: 7 of 8
A6: Teams
B7: Naam | C7: Nummer | D7: Gemiddelde
A8: =CONCATENATE("Baan ",D$4) -> Baan 1
A9: Sporter 1
A10: Sporter 2
A11: Sporter 3
B12: Naam | C12: Nummer
A13: =CONCATENATE("Baan ",D$4+1) -> Baan 2
A14: Sporter 1
A15: Sporter 2
A16: Sporter 3
B17: Naam | C17: Nummer
A18: =CONCATENATE("Baan ",D$4+2) -> Baan 3
A19: Sporter 1
A20: Sporter 2
A21: Sporter 3
B22: Naam | C22: Nummer
A23: =CONCATENATE("Baan ",D$4+3) -> Baan 4
A24: Sporter 1
A25: Sporter 2
A26: Sporter 3
B27: Naam | C27: Nummer
A28: =CONCATENATE("Baan ",D$4+4) -> Baan 5
A29: Sporter 1
A30: Sporter 2
A31: Sporter 3
B32: Naam | C32: Nummer
A33: =CONCATENATE("Baan ",D$4+5) -> Baan 6
A34: Sporter 1
A35: Sporter 2
A36: Sporter 3
B37: Naam | C37: Nummer
A38: =CONCATENATE("Baan ",D$4+6) -> Baan 7
A39: Sporter 1
A40: Sporter 2
...

Sheet Scores
B2: Wedstrijden | I2: set/matchpunten | AC2: =Deelnemers!D5 -> 7 of 8
A4: Ronde 1 | C4: Score | E4: Matchpunten | J4: Ronde | K4: 1 | M4: 2 | O4: 3 | Q4: 4 | S4: 5 | U4: 6 | W4: 7 | Y4: Tot. | Z4: Tot. | AA4: Sh-off
B5: =CONCATENATE(Wedstrijdschema!D5," - ",Wedstrijdschema!F5) -> 0 - 0 | E5: =IF(C5="",0,IF(AND(C5=0,D5=0),0,IF(C5=D5,1,IF(C5>D5,2,0)))) -> 0 | F5: =IF(C5="",0,IF(AND(C5=0,D5=0),0,IF(C5=D5,1,IF(C5<D5,2,0)))) -> 0 | H5: Pos. | I5: Naam | J5: Nummer | K5: S | L5: M | M5: S | N5: M | O5: S | P5: M | Q5: S | R5: M | S5: S | T5: M | U5: S | V5: M | W5: S | X5: M | Y5: Setp. | Z5: Matchp.
B6: =CONCATENATE(Wedstrijdschema!D6," - ",Wedstrijdschema!F6) -> 0 - 0 | E6: =IF(C6="",0,IF(AND(C6=0,D6=0),0,IF(C6=D6,1,IF(C6>D6,2,0)))) -> 0 | F6: =IF(C6="",0,IF(AND(C6=0,D6=0),0,IF(C6=D6,1,IF(C6<D6,2,0)))) -> 0 | H6: =IF(C$5<>"",RANK(Z6,Z$6:Z$13),"") | I6: =Deelnemers!B8 -> 0 | J6: =IF(I6<>"",Deelnemers!C8,"") -> 0 | K6: =C5 -> 0 | L6: =IF(C5<>"",E5,0) -> 0 | M6: =C11 -> 0 | N6: =IF(C11<>"",E11,0) -> 0 | O6: =C17 -> 0 | P6: =IF(C17<>"",E17,0) -> 0 | Q6: =C23 -> 0 | R6: =IF(C23<>"",E23,0) -> 0 | S6: =IF(B29=" - ",0,C29) -> 0 | T6: =IF(B29=" - ",0,E29) -> 0 | U6: =IF(B35=" - ",0,C35) -> 0 | V6: =IF(B35=" - ",0,E35) -> 0 | W6: =IF(B41=" - ",0,C41) -> 0 | X6: =IF(B41=" - ",0,E41) -> 0 | Y6: =IF(C$5<>"",K6+M6+O6+Q6+S6+U6+W6,0) -> 0 | Z6: =IF(C$5<>"",L6+N6+P6+R6+T6+V6+X6+(AA6/100),0) -> 0 | AC6: =IF(C$5<>"",_xlfn.RANK.EQ(AF6,AF$6:AF$13),"") | AD6: =Deelnemers!B8 -> 0 | AE6: =IF(AD6<>"",Deelnemers!C8,"") -> 0 | AF6: =IF(C$5<>"",L6+N6+P6+R6+T6+V6+X6+(AA6/100),0) -> 0 | AG6: =IF(AA6="","",AA6)
B7: =CONCATENATE(Wedstrijdschema!D7," - ",Wedstrijdschema!F7) -> 0 - 0 | E7: =IF(C7="",0,IF(AND(C7=0,D7=0),0,IF(C7=D7,1,IF(C7>D7,2,0)))) -> 0 | F7: =IF(C7="",0,IF(AND(C7=0,D7=0),0,IF(C7=D7,1,IF(C7<D7,2,0)))) -> 0 | H7: =IF(C$5<>"",RANK(Z7,Z$6:Z$13),"") | I7: =Deelnemers!B13 -> 0 | J7: =IF(I7<>"",Deelnemers!C13,"") -> 0 | K7: =D5 -> 0 | L7: =IF(C5<>"",F5,0) -> 0 | M7: =IF(AC2="1 of 2",D11,C12) -> 0 | N7: =IF(AC2="1 of 2",F11,E12) -> 0 | O7: =IF(AC2="1 of 2",D17,C18) -> 0 | P7: =IF(AC2="1 of 2",F17,E18) -> 0 | Q7: =IF(AC2="1 of 2",D23,IF(OR(AC2="5 of 6",AC2="7 of 8"),C24,D23)) -> 0 | R7: =IF(AC2="1 of 2",F23,IF(OR(AC2="5 of 6",AC2="7 of 8"),E24,F23)) -> 0 | S7: =IF(B29=" - ",0,C30) -> 0 | T7: =IF(B29=" - ",0,E30) -> 0 | U7: =IF(B35=" - ",0,C36) -> 0 | V7: =IF(B35=" - ",0,E36) -> 0 | W7: =IF(AC2="7 of 8",C42,0) -> 0 | X7: =IF(AC2="7 of 8",E42,0) -> 0 | Y7: =IF(C$5<>"",K7+M7+O7+Q7+S7+U7+W7,0) -> 0 | Z7: =IF(C$5<>"",L7+N7+P7+R7+T7+V7+X7+(AA7/100),0) -> 0 | AC7: =IF(C$5<>"",_xlfn.RANK.EQ(AF7,AF$6:AF$13),"") | AD7: =Deelnemers!B13 -> 0 | AE7: =IF(AD7<>"",Deelnemers!C13,"") -> 0 | AF7: =IF(C$5<>"",L7+N7+P7+R7+T7+V7+X7+(AA7/100),0) -> 0 | AG7: =IF(AA7="","",AA7)
B8: =CONCATENATE(Wedstrijdschema!D8," - ",Wedstrijdschema!F8) -> 0 - 0 | E8: =IF(C8="",0,IF(AND(C8=0,D8=0),0,IF(C8=D8,1,IF(C8>D8,2,0)))) -> 0 | F8: =IF(C8="",0,IF(AND(C8=0,D8=0),0,IF(C8=D8,1,IF(C8<D8,2,0)))) -> 0 | H8: =IF(Deelnemers!D5="1 of 2","",IF(C$5<>"",RANK(Z8,Z$6:Z$13),"")) | I8: =IF(Deelnemers!D5="1 of 2","",Deelnemers!B18) -> 0 | J8: =IF(I8<>"",Deelnemers!C18,"") -> 0 | K8: =IF(AC2="1 of 2",0,C6) -> 0 | L8: =IF(AC2="1 of 2",0,E6) -> 0 | M8: =IF(AC2="1 of 2",0,D11) -> 0 | N8: =IF(AC2="1 of 2",0,F11) -> 0 | O8: =IF(AC2="1 of 2",0,IF(AC2="3 of 4",D18,IF(OR(AC2="5 of 6",AC2="7 of 8"),C19,0))) -> 0 | P8: =IF(AC2="1 of 2",0,IF(AC2="3 of 4",F18,IF(OR(AC2="5 of 6",AC2="7 of 8"),E19,0))) -> 0 | Q8: =IF(AC2="1 of 2",0,IF(AC2="3 of 4",C24,IF(OR(AC2="5 of 6",AC2="7 of 8"),C25,0))) -> 0 | R8: =IF(AC2="1 of 2",0,IF(AC2="3 of 4",E24,IF(OR(AC2="5 of 6",AC2="7 of 8"),E25,0))) -> 0 | S8: =IF(AC2="1 of 2",0,IF(AC2="3 of 4",D29,IF(AC2="5 of 6",D30,IF(AC2="7 of 8",C31,0)))) -> 0 | T8: =IF(AC2="1 of 2",0,IF(AC2="3 of 4",F29,IF(AC2="5 of 6",F30,IF(AC2="7 of 8",E31,0)))) -> 0 | U8: =IF(AC2="1 of 2",0,IF(AC2="3 of 4",D36,IF(AC2="7 of 8",C37,0))) -> 0 | V8: =IF(AC2="1 of 2",0,IF(AC2="3 of 4",F36,IF(AC2="7 of 8",E37,0))) -> 0 | W8: =IF(AC2="7 of 8",D42,0) -> 0 | X8: =IF(AC2="7 of 8",F42,0) -> 0 | Y8: =IF(Deelnemers!D5=2,"",IF(C$5<>"",K8+M8+O8+Q8+S8+U8+W8,0)) -> 0 | Z8: =IF(Deelnemers!D5=2,"",IF(C$5<>"",L8+N8+P8+R8+T8+V8+X8+(AA8/100),0)) -> 0 | AC8: =IF(Deelnemers!D5="1 of 2","",IF(C$5<>"",_xlfn.RANK.EQ(AF8,AF$6:AF$13),"")) | AD8: =IF(Deelnemers!D5="1 of 2","",Deelnemers!B18) -> 0 | AE8: =IF(AD8<>"",Deelnemers!C18,"") -> 0 | AF8: =IF(Deelnemers!D5="1 of 2","",IF(C$5<>"",L8+N8+P8+R8+T8+V8+X8+(AA8/100),0)) -> 0 | AG8: =IF(AA8="","",AA8)
H9: =IF(Deelnemers!D5="1 of 2","",IF(C$5<>"",RANK(Z9,Z$6:Z$13),"")) | I9: =IF(Deelnemers!D5="1 of 2","",Deelnemers!B23) -> 0 | J9: =IF(I9<>"",Deelnemers!C23,"") -> 0 | K9: =IF(AC2="1 of 2",0,D6) -> 0 | L9: =IF(AC2="1 of 2",0,F6) -> 0 | M9: =IF(AC2="1 of 2",0,IF(AC2="3 of 4",D12,IF(OR(AC2="5 of 6",AC2="7 of 8"),C13,0))) -> 0 | N9: =IF(AC2="1 of 2",0,IF(AC2="3 of 4",F12,IF(OR(AC2="5 of 6",AC2="7 of 8"),E13,))) -> 0 | O9: =IF(AC2="1 of 2",0,IF(AC2="3 of 4",D17,IF(OR(AC2="5 of 6",AC2="7 of 8"),D17,0))) -> 0 | P9: =IF(AC2="1 of 2",0,IF(AC2="3 of 4",F17,IF(OR(AC2="5 of 6",AC2="7 of 8"),F17,1))) -> 0 | Q9: =IF(AC2="1 of 2",0,IF(OR(AC2="3 of 4",AC2="5 of 6"),D24,IF(AC2="7 of 8",C26,0))) -> 0 | R9: =IF(AC2="1 of 2",0,IF(OR(AC2="3 of 4",AC2="5 of 6"),F24,IF(AC2="7 of 8",E26,0))) -> 0 | S9: =IF(AC2="1 of 2",0,IF(AC2="3 of 4",D30,IF(AC2="5 of 6",C31,IF(AC2="7 of 8",C32,0)))) -> 0 | T9: =IF(AC2="1 of 2",0,IF(AC2="3 of 4",F30,IF(AC2="5 of 6",E31,IF(AC2="7 of 8",E32,0)))) -> 0 | U9: =IF(AC2="1 of 2",0,IF(AC2="3 of 4",D35,IF(AC2="7 of 8",D36,0))) -> 0 | V9: =IF(AC2="1 of 2",0,IF(AC2="3 of 4",F35,IF(AC2="7 of 8",F36,0))) -> 0 | W9: =IF(AC2="7 of 8",C43,0) -> 0 | X9: =IF(AC2="7 of 8",E43,0) -> 0 | Y9: =IF(Deelnemers!D5=2,"",IF(C$5<>"",K9+M9+O9+Q9+S9+U9+W9,0)) -> 0 | Z9: =IF(Deelnemers!D5=2,"",IF(C$5<>"",L9+N9+P9+R9+T9+V9+X9+(AA9/100),0)) -> 0 | AC9: =IF(Deelnemers!D5="1 of 2","",IF(C$5<>"",_xlfn.RANK.EQ(AF9,AF$6:AF$13),"")) | AD9: =IF(Deelnemers!D5="1 of 2","",Deelnemers!B23) -> 0 | AE9: =IF(AD9<>"",Deelnemers!C23,"") -> 0 | AF9: =IF(Deelnemers!D5="1 of 2","",IF(C$5<>"",L9+N9+P9+R9+T9+V9+X9+(AA9/100),0)) -> 0 | AG9: =IF(AA9="","",AA9)
A10: Ronde 2 | H10: =IF(OR(Deelnemers!D5="1 of 2",Deelnemers!D5="3 of 4"),"",IF(C$5<>"",RANK(Z10,Z$6:Z$13),"")) | I10: =IF(OR(Deelnemers!D5="1 of 2",Deelnemers!D5="3 of 4"),"",Deelnemers!B28) -> 0 | J10: =IF(I10<>"",Deelnemers!C28,"") -> 0 | K10: =IF(OR(AC2="1 of 2",AC2="3 of 4"),0,C7) -> 0 | L10: =IF(OR(AC2="1 of 2",AC2="3 of 4"),0,E7) -> 0 | M10: =IF(OR(AC2="1 of 2",AC2="3 of 4"),0,IF(OR(AC2="5 of 6",AC2="7 of 8"),D12,1)) -> 0 | N10: =IF(OR(AC2="1 of 2",AC2="3 of 4"),0,IF(OR(AC2="5 of 6",AC2="7 of 8"),F12,1)) -> 0 | O10: =IF(OR(AC2="1 of 2",AC2="3 of 4"),0,IF(AC2="5 of 6",D19,IF(AC2="7 of 8",C20,0))) -> 0 | P10: =IF(OR(AC2="1 of 2",AC2="3 of 4"),0,IF(AC2="5 of 6",F19,IF(AC2="7 of 8",E20,0))) -> 0 | Q10: =IF(OR(AC2="1 of 2",AC2="3 of 4"),0,IF(OR(AC2="5 of 6",AC2="7 of 8"),D23,1)) -> 0 | R10: =IF(OR(AC2="1 of 2",AC2="3 of 4"),0,IF(OR(AC2="5 of 6",AC2="7 of 8"),F23,1)) -> 0 | S10: =IF(OR(AC2="1 of 2",AC2="3 of 4"),0,IF(OR(AC2="5 of 6",AC2="7 of 8"),D31,0)) -> 0 | T10: =IF(OR(AC2="1 of 2",AC2="3 of 4"),0,IF(OR(AC2="5 of 6",AC2="7 of 8"),F31,1)) -> 0 | U10: =IF(OR(AC2="1 of 2",AC2="3 of 4"),0,IF(AC2="5 of 6",0,IF(AC2="7 of 8",C38,0))) -> 0 | V10: =IF(OR(AC2="1 of 2",AC2="3 of 4"),0,IF(AC2="5 of 6",0,IF(AC2="7 of 8",E38,0))) -> 0 | W10: =IF(AC2="7 of 8",D43,0) -> 0 | X10: =IF(AC2="7 of 8",F43,0) -> 0 | Y10: =IF(OR(Deelnemers!D5=2,Deelnemers!D5="3 of 4"),"",IF(C$5<>"",K10+M10+O10+Q10+S10+U10+W10,0)) -> 0 | Z10: =IF(OR(Deelnemers!D5=2,Deelnemers!D5="3 of 4"),"",IF(C$5<>"",L10+N10+P10+R10+T10+V10+X10+(AA10/100),0)) -> 0 | AC10: =IF(OR(Deelnemers!D5="1 of 2",Deelnemers!D5="3 of 4"),"",IF(C$5<>"",_xlfn.RANK.EQ(AF10,AF$6:AF$13),"")) | AD10: =IF(OR(Deelnemers!D5="1 of 2",Deelnemers!D5="3 of 4"),"",Deelnemers!B28) -> 0 | AE10: =IF(AD10<>"",Deelnemers!C28,"") -> 0 | AF10: =IF(OR(Deelnemers!D5="1 of 2",Deelnemers!D5="3 of 4"),"",IF(C$5<>"",L10+N10+P10+R10+T10+V10+X10+(AA10/100),0)) -> 0 | AG10: =IF(AA10="","",AA10)
B11: =CONCATENATE(Wedstrijdschema!D11," - ",Wedstrijdschema!F11) -> 0 - 0 | E11: =IF(C11="",0,IF(AND(C11=0,D11=0),0,IF(C11=D11,1,IF(C11>D11,2,0)))) -> 0 | F11: =IF(C11="",0,IF(AND(C11=0,D11=0),0,IF(C11=D11,1,IF(C11<D11,2,0)))) -> 0 | H11: =IF(OR(Deelnemers!D5="1 of 2",Deelnemers!D5="3 of 4")," ",IF(C$5<>"",RANK(Z11,Z$6:Z$13),"")) | I11: =IF(OR(Deelnemers!D5="1 of 2",Deelnemers!D5="3 of 4"),"",Deelnemers!B33) -> 0 | J11: =IF(I11<>"",Deelnemers!C33,"") -> 0 | K11: =IF(OR(AC2="1 of 2",AC2="3 of 4"),0,D7) -> 0 | L11: =IF(OR(AC2="1 of 2",AC2="3 of 4"),0,F7) -> 0 | M11: =IF(OR(AC2="1 of 2",AC2="3 of 4"),0,IF(AC2="5 of 6",D13,IF(AC2="7 of 8",C14,0))) -> 0 | N11: =IF(OR(AC2="1 of 2",AC2="3 of 4"),0,IF(AC2="5 of 6",F13,IF(AC2="7 of 8",E14,0))) -> 0 | O11: =IF(OR(AC2="1 of 2",AC2="3 of 4"),0,IF(OR(AC2="5 of 6",AC2="7 of 8"),D18,1)) -> 0 | P11: =IF(OR(AC2="1 of 2",AC2="3 of 4"),0,IF(OR(AC2="5 of 6",AC2="7 of 8"),F18,1)) -> 0 | Q11: =IF(OR(AC2="1 of 2",AC2="3 of 4"),0,IF(AC2="5 of 6",D25,IF(AC2="7 of 8",D26,0))) -> 0 | R11: =IF(OR(AC2="1 of 2",AC2="3 of 4"),0,IF(AC2="5 of 6",F25,IF(AC2="7 of 8",F26,0))) -> 0 | S11: =IF(OR(AC2="1 of 2",AC2="3 of 4"),0,IF(OR(AC2="5 of 6",AC2="7 of 8"),D29,0)) -> 0 | T11: =IF(OR(AC2="1 of 2",AC2="3 of 4"),0,IF(OR(AC2="5 of 6",AC2="7 of 8"),F29,0)) -> 0 | U11: =IF(OR(AC2="1 of 2",AC2="3 of 4"),0,IF(AC2="5 of 6",0,IF(AC2="7 of 8",D37,0))) -> 0 | V11: =IF(OR(AC2="1 of 2",AC2="3 of 4"),0,IF(AC2="5 of 6",0,IF(AC2="7 of 8",F37,0))) -> 0 | W11: =IF(AC2="7 of 8",C44,0) -> 0 | X11: =IF(AC2="7 of 8",E44,0) -> 0 | Y11: =IF(OR(Deelnemers!D5=2,Deelnemers!D5="3 of 4"),"",IF(C$5<>"",K11+M11+O11+Q11+S11+U11+W11,0)) -> 0 | Z11: =IF(OR(Deelnemers!D5=2,Deelnemers!D5="3 of 4"),"",IF(C$5<>"",L11+N11+P11+R11+T11+V11+X11+(AA11/100),0)) -> 0 | AC11: =IF(OR(Deelnemers!D5="1 of 2",Deelnemers!D5="3 of 4"),"",IF(C$5<>"",_xlfn.RANK.EQ(AF11,AF$6:AF$13),"")) | AD11: =IF(OR(Deelnemers!D5="1 of 2",Deelnemers!D5="3 of 4"),"",Deelnemers!B33) -> 0 | AE11: =IF(AD11<>"",Deelnemers!C33,"") -> 0 | AF11: =IF(OR(Deelnemers!D5="1 of 2",Deelnemers!D5="3 of 4"),"",IF(C$5<>"",L11+N11+P11+R11+T11+V11+X11+(AA11/100),0)) -> 0 | AG11: =IF(AA11="","",AA11)
B12: =CONCATENATE(Wedstrijdschema!D12," - ",Wedstrijdschema!F12) -> 0 - 0 | E12: =IF(C12="",0,IF(AND(C12=0,D12=0),0,IF(C12=D12,1,IF(C12>D12,2,0)))) -> 0 | F12: =IF(C12="",0,IF(AND(C12=0,D12=0),0,IF(C12=D12,1,IF(C12<D12,2,0)))) -> 0 | H12: =IF(Deelnemers!D5<>"7 of 8"," ",IF(C$5<>"",RANK(Z12,Z$6:Z$13),"")) | I12: =IF(Deelnemers!D5="7 of 8",Deelnemers!B38,"") -> 0 | J12: =IF(I12<>"",Deelnemers!C38,"") -> 0 | K12: =IF(AC2="7 of 8",C8,0) -> 0 | L12: =IF(AC2="7 of 8",E8,0) -> 0 | M12: =IF(AC2="7 of 8",D13,0) -> 0 | N12: =IF(AC2="7 of 8",F13,0) -> 0 | O12: =IF(AC2="7 of 8",D20,0) -> 0 | P12: =IF(AC2="7 of 8",F20,0) -> 0 | Q12: =IF(AC2="7 of 8",D25,0) -> 0 | R12: =IF(AC2="7 of 8",F25,0) -> 0 | S12: =IF(AC2="7 of 8",D30,0) -> 0 | T12: =IF(AC2="7 of 8",F30,0) -> 0 | U12: =IF(AC2="7 of 8",D35,0) -> 0 | V12: =IF(AC2="7 of 8",F35,0) -> 0 | W12: =IF(AC2="7 of 8",D44,0) -> 0 | X12: =IF(AC2="7 of 8",F44,0) -> 0 | Y12: =IF(Deelnemers!D5<>"7 of 8","",IF(C$5<>"",K12+M12+O12+Q12+S12+U12+W12,0)) -> 0 | Z12: =IF(Deelnemers!D5<>"7 of 8","",IF(C$5<>"",L12+N12+P12+R12+T12+V12+X12+(AA12/100),0)) -> 0 | AC12: =IF(Deelnemers!D5<>"7 of 8","",IF(C$5<>"",_xlfn.RANK.EQ(AF12,AF$6:AF$13),"")) | AD12: =IF(Deelnemers!D5="7 of 8",Deelnemers!B38,"") -> 0 | AE12: =IF(AD12<>"",Deelnemers!C38,"") -> 0 | AF12: =IF(Deelnemers!D5<>"7 of 8","",IF(C$5<>"",L12+N12+P12+R12+T12+V12+X12+(AA12/100),0)) -> 0 | AG12: =IF(AA12="","",AA12)
B13: =CONCATENATE(Wedstrijdschema!D13," - ",Wedstrijdschema!F13) -> 0 - 0 | E13: =IF(C13="",0,IF(AND(C13=0,D13=0),0,IF(C13=D13,1,IF(C13>D13,2,0)))) -> 0 | F13: =IF(C13="",0,IF(AND(C13=0,D13=0),0,IF(C13=D13,1,IF(C13<D13,2,0)))) -> 0 | H13: =IF(Deelnemers!D5<>"7 of 8"," ",IF(C$5<>"",RANK(Z13,Z$6:Z$13),"")) | I13: =IF(Deelnemers!D5="7 of 8",Deelnemers!B43,"") -> 0 | J13: =IF(I13<>"",Deelnemers!C43,"") -> 0 | K13: =IF(AC2="7 of 8",D8,0) -> 0 | L13: =IF(AC2="7 of 8",F8,0) -> 0 | M13: =IF(AC2="7 of 8",D14,0) -> 0 | N13: =IF(AC2="7 of 8",F14,0) -> 0 | O13: =IF(AC2="7 of 8",D19,0) -> 0 | P13: =IF(AC2="7 of 8",F19,0) -> 0 | Q13: =IF(AC2="7 of 8",D24,0) -> 0 | R13: =IF(AC2="7 of 8",F24,0) -> 0 | S13: =IF(AC2="7 of 8",D32,0) -> 0 | T13: =IF(AC2="7 of 8",F32,0) -> 0 | U13: =IF(AC2="7 of 8",D38,0) -> 0 | V13: =IF(AC2="7 of 8",F38,0) -> 0 | W13: =IF(AC2="7 of 8",D41,0) -> 0 | X13: =IF(AC2="7 of 8",F41,0) -> 0 | Y13: =IF(Deelnemers!D5<>"7 of 8","",IF(C$5<>"",K13+M13+O13+Q13+S13+U13+W13,0)) -> 0 | Z13: =IF(Deelnemers!D5<>"7 of 8","",IF(C$5<>"",L13+N13+P13+R13+T13+V13+X13+(AA13/100),0)) -> 0 | AC13: =IF(Deelnemers!D5<>"7 of 8","",IF(C$5<>"",_xlfn.RANK.EQ(AF13,AF$6:AF$13),"")) | AD13: =IF(Deelnemers!D5="7 of 8",Deelnemers!B43,"") -> 0 | AE13: =IF(AD13<>"",Deelnemers!C43,"") -> 0 | AF13: =IF(Deelnemers!D5<>"7 of 8","",IF(C$5<>"",L13+N13+P13+R13+T13+V13+X13+(AA13/100),0)) -> 0 | AG13: =IF(AA13="","",AA13)
B14: =CONCATENATE(Wedstrijdschema!D14," - ",Wedstrijdschema!F14) -> 0 - 0 | E14: =IF(C14="",0,IF(AND(C14=0,D14=0),0,IF(C14=D14,1,IF(C14>D14,2,0)))) -> 0 | F14: =IF(C14="",0,IF(AND(C14=0,D14=0),0,IF(C14=D14,1,IF(C14<D14,2,0)))) -> 0
AC15: Gesorteerd op rang
A16: Ronde 3 | I16: Voor printen tussenstand klik op de printer of selecteer afdrukken | AC16: {=_xlfn._xlws.SORT(AC6:AG13,1,1)} | AD16: 0 | AE16: 0 | AF16: 0
B17: =CONCATENATE(Wedstrijdschema!D17," - ",Wedstrijdschema!F17) -> 0 - 0 | E17: =IF(C17="",0,IF(AND(C17=0,D17=0),0,IF(C17=D17,1,IF(C17>D17,2,0)))) -> 0 | F17: =IF(C17="",0,IF(AND(C17=0,D17=0),0,IF(C17=D17,1,IF(C17<D17,2,0)))) -> 0 | AD17: 0 | AE17: 0 | AF17: 0
B18: =CONCATENATE(Wedstrijdschema!D18," - ",Wedstrijdschema!F18) -> 0 - 0 | E18: =IF(C18="",0,IF(AND(C18=0,D18=0),0,IF(C18=D18,1,IF(C18>D18,2,0)))) -> 0 | F18: =IF(C18="",0,IF(AND(C18=0,D18=0),0,IF(C18=D18,1,IF(C18<D18,2,0)))) -> 0 | I18: LET OP indien hierboven nog rode cellen zijn dan MOET er een shoot-off geschoten worden | AD18: 0 | AE18: 0 | AF18: 0
B19: =CONCATENATE(Wedstrijdschema!D19," - ",Wedstrijdschema!F19) -> 0 - 0 | E19: =IF(C19="",0,IF(AND(C19=0,D19=0),0,IF(C19=D19,1,IF(C19>D19,2,0)))) -> 0 | F19: =IF(C19="",0,IF(AND(C19=0,D19=0),0,IF(C19=D19,1,IF(C19<D19,2,0)))) -> 0 | I19: Dit betreft namelijk medaille plaatsen. | AD19: 0 | AE19: 0 | AF19: 0
B20: =CONCATENATE(Wedstrijdschema!D20," - ",Wedstrijdschema!F20) -> 0 - 0 | E20: =IF(C20="",0,IF(AND(C20=0,D20=0),0,IF(C20=D20,1,IF(C20>D20,2,0)))) -> 0 | F20: =IF(C20="",0,IF(AND(C20=0,D20=0),0,IF(C20=D20,1,IF(C20<D20,2,0)))) -> 0 | I20: Kijk goed welke plaatsen tegen elkaar moeten. | AD20: 0 | AE20: 0 | AF20: 0
AD21: 0 | AE21: 0 | AF21: 0
A22: Ronde 4 | AD22: 0 | AE22: 0 | AF22: 0
B23: =CONCATENATE(Wedstrijdschema!D23," - ",Wedstrijdschema!F23) -> 0 - 0 | E23: =IF(C23="",0,IF(AND(C23=0,D23=0),0,IF(C23=D23,1,IF(C23>D23,2,0)))) -> 0 | F23: =IF(C23="",0,IF(AND(C23=0,D23=0),0,IF(C23=D23,1,IF(C23<D23,2,0)))) -> 0 | AD23: 0 | AE23: 0 | AF23: 0
B24: =CONCATENATE(Wedstrijdschema!D24," - ",Wedstrijdschema!F24) -> 0 - 0 | E24: =IF(C24="",0,IF(AND(C24=0,D24=0),0,IF(C24=D24,1,IF(C24>D24,2,0)))) -> 0 | F24: =IF(C24="",0,IF(AND(C24=0,D24=0),0,IF(C24=D24,1,IF(C24<D24,2,0)))) -> 0
B25: =CONCATENATE(Wedstrijdschema!D25," - ",Wedstrijdschema!F25) -> 0 - 0 | E25: =IF(C25="",0,IF(AND(C25=0,D25=0),0,IF(C25=D25,1,IF(C25>D25,2,0)))) -> 0 | F25: =IF(C25="",0,IF(AND(C25=0,D25=0),0,IF(C25=D25,1,IF(C25<D25,2,0)))) -> 0
B26: =CONCATENATE(Wedstrijdschema!D26," - ",Wedstrijdschema!F26) -> 0 - 0 | E26: =IF(C26="",0,IF(AND(C26=0,D26=0),0,IF(C26=D26,1,IF(C26>D26,2,0)))) -> 0 | F26: =IF(C26="",0,IF(AND(C26=0,D26=0),0,IF(C26=D26,1,IF(C26<D26,2,0)))) -> 0
A28: Ronde 5
B29: =CONCATENATE(Wedstrijdschema!D29," - ",Wedstrijdschema!F29) -> 0 - 0 | E29: =IF(C29="",0,IF(AND(C29=0,D29=0),0,IF(C29=D29,1,IF(C29>D29,2,0)))) -> 0 | F29: =IF(C29="",0,IF(AND(C29=0,D29=0),0,IF(C29=D29,1,IF(C29<D29,2,0)))) -> 0
B30: =CONCATENATE(Wedstrijdschema!D30," - ",Wedstrijdschema!F30) -> 0 - 0 | E30: =IF(C30="",0,IF(AND(C30=0,D30=0),0,IF(C30=D30,1,IF(C30>D30,2,0)))) -> 0 | F30: =IF(C30="",0,IF(AND(C30=0,D30=0),0,IF(C30=D30,1,IF(C30<D30,2,0)))) -> 0
B31: =CONCATENATE(Wedstrijdschema!D31," - ",Wedstrijdschema!F31) -> 0 - 0 | E31: =IF(C31="",0,IF(AND(C31=0,D31=0),0,IF(C31=D31,1,IF(C31>D31,2,0)))) -> 0 | F31: =IF(C31="",0,IF(AND(C31=0,D31=0),0,IF(C31=D31,1,IF(C31<D31,2,0)))) -> 0
B32: =CONCATENATE(Wedstrijdschema!D32," - ",Wedstrijdschema!F32) -> 0 - 0 | E32: =IF(C32="",0,IF(AND(C32=0,D32=0),0,IF(C32=D32,1,IF(C32>D32,2,0)))) -> 0 | F32: =IF(C32="",0,IF(AND(C32=0,D32=0),0,IF(C32=D32,1,IF(C32<D32,2,0)))) -> 0
A34: Ronde 6
B35: =CONCATENATE(Wedstrijdschema!D35," - ",Wedstrijdschema!F35) -> 0 - 0 | E35: =IF(C35="",0,IF(AND(C35=0,D35=0),0,IF(C35=D35,1,IF(C35>D35,2,0)))) -> 0 | F35: =IF(C35="",0,IF(AND(C35=0,D35=0),0,IF(C35=D35,1,IF(C35<D35,2,0)))) -> 0
B36: =CONCATENATE(Wedstrijdschema!D36," - ",Wedstrijdschema!F36) -> 0 - 0 | E36: =IF(C36="",0,IF(AND(C36=0,D36=0),0,IF(C36=D36,1,IF(C36>D36,2,0)))) -> 0 | F36: =IF(C36="",0,IF(AND(C36=0,D36=0),0,IF(C36=D36,1,IF(C36<D36,2,0)))) -> 0
B37: =CONCATENATE(Wedstrijdschema!D37," - ",Wedstrijdschema!F37) -> 0 - 0 | E37: =IF(C37="",0,IF(AND(C37=0,D37=0),0,IF(C37=D37,1,IF(C37>D37,2,0)))) -> 0 | F37: =IF(C37="",0,IF(AND(C37=0,D37=0),0,IF(C37=D37,1,IF(C37<D37,2,0)))) -> 0
B38: =CONCATENATE(Wedstrijdschema!D38," - ",Wedstrijdschema!F38) -> 0 - 0 | E38: =IF(C38="",0,IF(AND(C38=0,D38=0),0,IF(C38=D38,1,IF(C38>D38,2,0)))) -> 0 | F38: =IF(C38="",0,IF(AND(C38=0,D38=0),0,IF(C38=D38,1,IF(C38<D38,2,0)))) -> 0
A40: Ronde 7
B41: =CONCATENATE(Wedstrijdschema!D41," - ",Wedstrijdschema!F41) -> 0 - 0 | E41: =IF(C41="",0,IF(AND(C41=0,D41=0),0,IF(C41=D41,1,IF(C41>D41,2,0)))) -> 0 | F41: =IF(C41="",0,IF(AND(C41=0,D41=0),0,IF(C41=D41,1,IF(C41<D41,2,0)))) -> 0
B42: =CONCATENATE(Wedstrijdschema!D42," - ",Wedstrijdschema!F42) -> 0 - 0 | E42: =IF(C42="",0,IF(AND(C42=0,D42=0),0,IF(C42=D42,1,IF(C42>D42,2,0)))) -> 0 | F42: =IF(C42="",0,IF(AND(C42=0,D42=0),0,IF(C42=D42,1,IF(C42<D42,2,0)))) -> 0
B43: =CONCATENATE(Wedstrijdschema!D43," - ",Wedstrijdschema!F43) -> 0 - 0 | E43: =IF(C43="",0,IF(AND(C43=0,D43=0),0,IF(C43=D43,1,IF(C43>D43,2,0)))) -> 0 | F43: =IF(C43="",0,IF(AND(C43=0,D43=0),0,IF(C43=D43,1,IF(C43<D43,2,0)))) -> 0
B44: =CONCATENATE(Wedstrijdschema!D44," - ",Wedstrijdschema!F44) -> 0 - 0 | E44: =IF(C44="",0,IF(AND(C44=0,D44=0),0,IF(C44=D44,1,IF(C44>D44,2,0)))) -> 0 | F44: =IF(C44="",0,IF(AND(C44=0,D44=0),0,IF(C44=D44,1,IF(C44<D44,2,0)))) -> 0

Sheet Stand
B2: ="Uitslag "&Deelnemers!B1 -> Uitslag RK Teams Rayon 4, 25m 1pijl competitie 2025/2026
B3: =Deelnemers!B2 -> Recurve klasse D
B4: =IF(Deelnemers!B3="","",Deelnemers!B3) -> Willem Tell 1921, Kerkrade
B5: =IF(Deelnemers!B4="","",Deelnemers!B4) -> 2026-04-11
B7: Plaats | C7: Team | D7: Ver.Nummer | E7: Matchpunten | F7: Shoot-off
B8: =Scores!AC16 | C8: =Scores!AD16 -> 0 | D8: =Scores!AE16 -> 0 | E8: =Scores!AF16 -> 0 | F8: =IF(Scores!AG16<>"",Scores!AG16,"") | G8: Rayonkampioen
B9: =Scores!AC17 | C9: =Scores!AD17 -> 0 | D9: =Scores!AE17 -> 0 | E9: =Scores!AF17 -> 0 | F9: =IF(Scores!AG17<>"",Scores!AG17,"") | G9: 2e
B10: =Scores!AC18 | C10: =Scores!AD18 -> 0 | D10: =Scores!AE18 -> 0 | E10: =Scores!AF18 -> 0 | F10: =IF(Scores!AG18<>"",Scores!AG18,"") | G10: =IF(Scores!AC2=2,"","3e") -> 3e
B11: =Scores!AC19 | C11: =Scores!AD19 -> 0 | D11: =Scores!AE19 -> 0 | E11: =Scores!AF19 -> 0 | F11: =IF(Scores!AG19<>"",Scores!AG19,"")
B12: =Scores!AC20 | C12: =Scores!AD20 -> 0 | D12: =Scores!AE20 -> 0 | E12: =Scores!AF20 -> 0 | F12: =IF(Scores!AG20<>"",Scores!AG20,"")
B13: =Scores!AC21 | C13: =Scores!AD21 -> 0 | D13: =Scores!AE21 -> 0 | E13: =Scores!AF21 -> 0 | F13: =IF(Scores!AG21<>"",Scores!AG21,"")
B14: =Scores!AC22 | C14: =Scores!AD22 -> 0 | D14: =Scores!AE22 -> 0 | E14: =Scores!AF22 -> 0 | F14: =IF(Scores!AG22<>"",Scores!AG22,"")
B15: =Scores!AC23 | C15: =Scores!AD23 -> 0 | D15: =Scores!AE23 -> 0 | E15: =Scores!AF23 -> 0 | F15: =IF(Scores!AG23<>"",Scores!AG23,"")

Sheet Wedstrijdschema
A1: Wedstrijd schema | K1: Deelnemers: | L1: =Deelnemers!D5 -> 7 of 8
A2: =Deelnemers!B2 -> Recurve klasse D | K2: ronde | L2: Wedstr 1 | N2: Wedstr 2 | P2: Wedstr 3 | R2: Wedstr 4
K3: 1 | L3: =Deelnemers!A8 -> Baan 1 | M3: =Deelnemers!A13 -> Baan 2 | N3: =IF(Deelnemers!D5="1 of 2","",Deelnemers!A18) -> Baan 3 | O3: =IF(Deelnemers!D5="1 of 2","",Deelnemers!A23) -> Baan 4 | P3: =IF(Deelnemers!D5="1 of 2","",IF(L1="3 of 4","",Deelnemers!A28)) -> Baan 5 | Q3: =IF(Deelnemers!D5="1 of 2","",IF(L1="3 of 4","",Deelnemers!A33)) -> Baan 6 | R3: =IF(L1="7 of 8",Deelnemers!A38,"") -> Baan 7 | S3: =IF(L1="7 of 8",Deelnemers!A43,"") -> Baan 8
A4: Ronde 1 | K4: 2 | L4: =Deelnemers!A8 -> Baan 1 | M4: =IF(Deelnemers!D5="1 of 2",Deelnemers!A13,Deelnemers!A18) -> Baan 3 | N4: =IF(Deelnemers!D5="1 of 2","",Deelnemers!A13) -> Baan 2 | O4: =IF(Deelnemers!D5="1 of 2","",IF(L1="3 of 4",Deelnemers!A23,Deelnemers!A28)) -> Baan 5 | P4: =IF(Deelnemers!D5="1 of 2","",IF(L1="3 of 4","",Deelnemers!A23)) -> Baan 4 | Q4: =IF(Deelnemers!D5="1 of 2","",IF(L1="3 of 4","",IF(L1="7 of 8",Deelnemers!A38,Deelnemers!A33))) -> Baan 7 | R4: =IF(L1="7 of 8",Deelnemers!A33,"") -> Baan 6 | S4: =IF(L1="7 of 8",Deelnemers!A43,"") -> Baan 8
A5: =L3 -> Baan 1 | B5: - | C5: =M3 -> Baan 2 | D5: =VLOOKUP(A5,Deelnemers!A:D,2,FALSE()) -> 0 | E5: - | F5: =VLOOKUP(C5,Deelnemers!A:D,2,FALSE()) -> 0 | K5: 3 | L5: =Deelnemers!A8 -> Baan 1 | M5: =IF(Deelnemers!D5="1 of 2",Deelnemers!A13,Deelnemers!A23) -> Baan 4 | N5: =IF(Deelnemers!D5="1 of 2","",Deelnemers!A13) -> Baan 2 | O5: =IF(Deelnemers!D5="1 of 2","",IF(L1="3 of 4",Deelnemers!A18,Deelnemers!A33)) -> Baan 6 | P5: =IF(Deelnemers!D5="1 of 2","",IF(L1="3 of 4","",Deelnemers!A18)) -> Baan 3 | Q5: =IF(Deelnemers!D5="1 of 2","",IF(L1="3 of 4","",IF(L1="7 of 8",Deelnemers!A43,Deelnemers!A28))) -> Baan 8 | R5: =IF(L1="7 of 8",Deelnemers!A28,"") -> Baan 5 | S5: =IF(L1="7 of 8",Deelnemers!A38,"") -> Baan 7
A6: =N3 -> Baan 3 | B6: - | C6: =O3 -> Baan 4 | D6: =IF(A6="","",VLOOKUP(A6,Deelnemers!A:D,2,FALSE())) -> 0 | E6: - | F6: =IF(A6="","",VLOOKUP(C6,Deelnemers!A:D,2,FALSE())) -> 0 | K6: 4 | L6: =Deelnemers!A8 -> Baan 1 | M6: =IF(Deelnemers!D5="1 of 2",Deelnemers!A13,IF(L1="3 of 4",Deelnemers!A13,Deelnemers!A28)) -> Baan 5 | N6: =IF(Deelnemers!D5="1 of 2","",IF(L1="3 of 4",Deelnemers!A18,Deelnemers!A13)) -> Baan 2 | O6: =IF(Deelnemers!D5="1 of 2","",IF(L1="7 of 8",Deelnemers!A43,Deelnemers!A23)) -> Baan 8 | P6: =IF(Deelnemers!D5="1 of 2","",IF(L1="3 of 4","",Deelnemers!A18)) -> Baan 3 | Q6: =IF(Deelnemers!D5="1 of 2","",IF(L1="3 of 4","",IF(L1="7 of 8",Deelnemers!A38,Deelnemers!A33))) -> Baan 7 | R6: =IF(L1="7 of 8",Deelnemers!A23,"") -> Baan 4 | S6: =IF(L1="7 of 8",Deelnemers!A33,"") -> Baan 6
A7: =P3 -> Baan 5 | B7: - | C7: =Q3 -> Baan 6 | D7: =IF(A7="","",VLOOKUP(A7,Deelnemers!A:D,2,FALSE())) -> 0 | E7: - | F7: =IF(C7="","",VLOOKUP(C7,Deelnemers!A:D,2,FALSE())) -> 0 | K7: =IF(L1="1 of 2","",5) -> 5 | L7: =IF(Deelnemers!D5="1 of 2","",Deelnemers!A8) -> Baan 1 | M7: =IF(Deelnemers!D5="1 of 2","",IF(L1="3 of 4",Deelnemers!A18,Deelnemers!A33)) -> Baan 6 | N7: =IF(Deelnemers!D5="1 of 2","",Deelnemers!A13) -> Baan 2 | O7: =IF(Deelnemers!D5="1 of 2","",IF(L1="3 of 4",Deelnemers!A23,IF(L1="7 of 8",Deelnemers!A38,Deelnemers!A18))) -> Baan 7 | P7: =IF(Deelnemers!D5="1 of 2","",IF(L1="3 of 4","",IF(L1="7 of 8",Deelnemers!A18,Deelnemers!A23))) -> Baan 3 | Q7: =IF(Deelnemers!D5="1 of 2","",IF(L1="3 of 4","",IF(L1="7 of 8",Deelnemers!A28,Deelnemers!A28))) -> Baan 5 | R7: =IF(L1="7 of 8",Deelnemers!A23,"") -> Baan 4 | S7: =IF(L1="7 of 8",Deelnemers!A43,"") -> Baan 8
A8: =R3 -> Baan 7 | B8: - | C8: =S3 -> Baan 8 | D8: =IF(A8="","",VLOOKUP(A8,Deelnemers!A:D,2,FALSE())) -> 0 | E8: - | F8: =IF(C8="","",VLOOKUP(C8,Deelnemers!A:D,2,FALSE())) -> 0 | K8: =IF(L1="1 of 2","",IF(L1="5 of 6","",6)) -> 6 | L8: =IF(K8=6,Deelnemers!A8,"") -> Baan 1 | M8: =IF(L1="3 of 4",Deelnemers!A23,IF(L1="7 of 8",Deelnemers!A38,"")) -> Baan 7 | N8: =IF(Deelnemers!D5="1 of 2","",IF(L1="5 of 6","",Deelnemers!A13)) -> Baan 2 | O8: =IF(Deelnemers!D5="1 of 2","",IF(L1="3 of 4",Deelnemers!A18,IF(L1="7 of 8",Deelnemers!A23,""))) -> Baan 4 | P8: =IF(L1="7 of 8",Deelnemers!A18,"") -> Baan 3 | Q8: =IF(L1="7 of 8",Deelnemers!A33,"") -> Baan 6 | R8: =IF(L1="7 of 8",Deelnemers!A28,"") -> Baan 5 | S8: =IF(L1="7 of 8",Deelnemers!A43,"") -> Baan 8
K9: =IF(L1="7 of 8",7,"") -> 7 | L9: =IF(K9=7,Deelnemers!A8,"") -> Baan 1 | M9: =IF(L1="7 of 8",Deelnemers!A43,"") -> Baan 8 | N9: =IF(L1="7 of 8",Deelnemers!A13,"") -> Baan 2 | O9: =IF(L1="7 of 8",Deelnemers!A18,"") -> Baan 3 | P9: =IF(L1="7 of 8",Deelnemers!A23,"") -> Baan 4 | Q9: =IF(L1="7 of 8",Deelnemers!A28,"") -> Baan 5 | R9: =IF(L1="7 of 8",Deelnemers!A33,"") -> Baan 6 | S9: =IF(L1="7 of 8",Deelnemers!A38,"") -> Baan 7
A10: Ronde 2
A11: =L4 -> Baan 1 | B11: - | C11: =M4 -> Baan 3 | D11: =VLOOKUP(A11,Deelnemers!A:D,2,FALSE()) -> 0 | E11: - | F11: =VLOOKUP(C11,Deelnemers!A:D,2,FALSE()) -> 0
A12: =N4 -> Baan 2 | B12: - | C12: =O4 -> Baan 5 | D12: =IF(A12="","",VLOOKUP(A12,Deelnemers!A:D,2,FALSE())) -> 0 | E12: - | F12: =IF(C12="","",VLOOKUP(C12,Deelnemers!A:D,2,FALSE())) -> 0
A13: =P4 -> Baan 4 | B13: - | C13: =Q4 -> Baan 7 | D13: =IF(A13="","",VLOOKUP(A13,Deelnemers!A:D,2,FALSE())) -> 0 | E13: - | F13: =IF(C13="","",VLOOKUP(C13,Deelnemers!A:D,2,FALSE())) -> 0
A14: =R4 -> Baan 6 | B14: - | C14: =S4 -> Baan 8 | D14: =IF(A14="","",VLOOKUP(A14,Deelnemers!A:D,2,FALSE())) -> 0 | E14: - | F14: =IF(C14="","",VLOOKUP(C14,Deelnemers!A:D,2,FALSE())) -> 0
A16: Ronde 3
A17: =L5 -> Baan 1 | B17: - | C17: =M5 -> Baan 4 | D17: =VLOOKUP(A17,Deelnemers!A:D,2,FALSE()) -> 0 | E17: - | F17: =VLOOKUP(C17,Deelnemers!A:D,2,FALSE()) -> 0
A18: =N5 -> Baan 2 | B18: - | C18: =O5 -> Baan 6 | D18: =IF(A18="","",VLOOKUP(A18,Deelnemers!A:D,2,FALSE())) -> 0 | E18: - | F18: =IF(C18="","",VLOOKUP(C18,Deelnemers!A:D,2,FALSE())) -> 0
A19: =P5 -> Baan 3 | B19: - | C19: =Q5 -> Baan 8 | D19: =IF(A19="","",VLOOKUP(A19,Deelnemers!A:D,2,FALSE())) -> 0 | E19: - | F19: =IF(C19="","",VLOOKUP(C19,Deelnemers!A:D,2,FALSE())) -> 0
A20: =R5 -> Baan 5 | B20: - | C20: =S5 -> Baan 7 | D20: =IF(A20="","",VLOOKUP(A20,Deelnemers!A:D,2,FALSE())) -> 0 | E20: - | F20: =IF(C20="","",VLOOKUP(C20,Deelnemers!A:D,2,FALSE())) -> 0
A22: Ronde 4
A23: =L6 -> Baan 1 | B23: - | C23: =M6 -> Baan 5 | D23: =VLOOKUP(A23,Deelnemers!A:D,2,FALSE()) -> 0 | E23: - | F23: =VLOOKUP(C23,Deelnemers!A:D,2,FALSE()) -> 0
A24: =N6 -> Baan 2 | B24: - | C24: =O6 -> Baan 8 | D24: =IF(A24="","",VLOOKUP(A24,Deelnemers!A:D,2,FALSE())) -> 0 | E24: - | F24: =IF(C24="","",VLOOKUP(C24,Deelnemers!A:D,2,FALSE())) -> 0
A25: =P6 -> Baan 3 | B25: - | C25: =Q6 -> Baan 7 | D25: =IF(A25="","",VLOOKUP(A25,Deelnemers!A:D,2,FALSE())) -> 0 | E25: - | F25: =IF(C25="","",VLOOKUP(C25,Deelnemers!A:D,2,FALSE())) -> 0
A26: =R6 -> Baan 4 | B26: - | C26: =S6 -> Baan 6 | D26: =IF(A26="","",VLOOKUP(A26,Deelnemers!A:D,2,FALSE())) -> 0 | E26: - | F26: =IF(C26="","",VLOOKUP(C26,Deelnemers!A:D,2,FALSE())) -> 0
A28: =IF(K7=5,"Ronde 5","") -> Ronde 5
A29: =L7 -> Baan 1 | B29: - | C29: =M7 -> Baan 6 | D29: =IF(A29="","",VLOOKUP(A29,Deelnemers!A:D,2,FALSE())) -> 0 | E29: - | F29: =IF(C29="","",VLOOKUP(C29,Deelnemers!A:D,2,FALSE())) -> 0
A30: =N7 -> Baan 2 | B30: - | C30: =O7 -> Baan 7 | D30: =IF(A30="","",VLOOKUP(A30,Deelnemers!A:D,2,FALSE())) -> 0 | E30: - | F30: =IF(C30="","",VLOOKUP(C30,Deelnemers!A:D,2,FALSE())) -> 0
A31: =P7 -> Baan 3 | B31: - | C31: =Q7 -> Baan 5 | D31: =IF(A31="","",VLOOKUP(A31,Deelnemers!A:D,2,FALSE())) -> 0 | E31: - | F31: =IF(C31="","",VLOOKUP(C31,Deelnemers!A:D,2,FALSE())) -> 0
A32: =R7 -> Baan 4 | B32: - | C32: =S7 -> Baan 8 | D32: =IF(A32="","",VLOOKUP(A32,Deelnemers!A:D,2,FALSE())) -> 0 | E32: - | F32: =IF(C32="","",VLOOKUP(C32,Deelnemers!A:D,2,FALSE())) -> 0
A34: =IF(K8=6,"Ronde 6","") -> Ronde 6
A35: =L8 -> Baan 1 | B35: - | C35: =M8 -> Baan 7 | D35: =IF(A35="","",VLOOKUP(A35,Deelnemers!A:D,2,FALSE())) -> 0 | E35: - | F35: =IF(A35="","",VLOOKUP(C35,Deelnemers!A:D,2,FALSE())) -> 0
A36: =N8 -> Baan 2 | B36: - | C36: =O8 -> Baan 4 | D36: =IF(A35="","",VLOOKUP(A36,Deelnemers!A:D,2,FALSE())) -> 0 | E36: - | F36: =IF(A35="","",VLOOKUP(C36,Deelnemers!A:D,2,FALSE())) -> 0
A37: =P8 -> Baan 3 | B37: - | C37: =Q8 -> Baan 6 | D37: =IF(A37="","",VLOOKUP(A37,Deelnemers!A:D,2,FALSE())) -> 0 | E37: - | F37: =IF(C37="","",VLOOKUP(C37,Deelnemers!A:D,2,FALSE())) -> 0
A38: =R8 -> Baan 5 | B38: - | C38: =S8 -> Baan 8 | D38: =IF(A38="","",VLOOKUP(A38,Deelnemers!A:D,2,FALSE())) -> 0 | E38: - | F38: =IF(C38="","",VLOOKUP(C38,Deelnemers!A:D,2,FALSE())) -> 0
A40: =IF(K9=7,"Ronde 7","") -> Ronde 7
A41: =L9 -> Baan 1 | B41: - | C41: =M9 -> Baan 8 | D41: =IF(A41="","",VLOOKUP(A41,Deelnemers!A:D,2,FALSE())) -> 0 | E41: - | F41: =IF(C41="","",VLOOKUP(C41,Deelnemers!A:D,2,FALSE())) -> 0
A42: =N9 -> Baan 2 | B42: - | C42: =O9 -> Baan 3 | D42: =IF(A42="","",VLOOKUP(A42,Deelnemers!A:D,2,FALSE())) -> 0 | E42: - | F42: =IF(C42="","",VLOOKUP(C42,Deelnemers!A:D,2,FALSE())) -> 0
A43: =P9 -> Baan 4 | B43: - | C43: =Q9 -> Baan 5 | D43: =IF(A43="","",VLOOKUP(A43,Deelnemers!A:D,2,FALSE())) -> 0 | E43: - | F43: =IF(C43="","",VLOOKUP(C43,Deelnemers!A:D,2,FALSE())) -> 0
A44: =R9 -> Baan 6 | B44: - | C44: =S9 -> Baan 7 | D44: =IF(A44="","",VLOOKUP(A44,Deelnemers!A:D,2,FALSE())) -> 0 | E44: - | F44: =IF(C44="","",VLOOKUP(C44,Deelnemers!A:D,2,FALSE())) -> 0

Sheet Score briefjes Indoor
C2: =VLOOKUP(Z2,AA14:AI21,2,FALSE()) -> Baan 1 | I2: =Z2 -> Ronde 1 | R2: =VLOOKUP(Z2,AA14:AI21,3,FALSE()) -> Baan 2 | X2: Welke ronde? | Y2: 1 | Z2: =CONCATENATE("Ronde"," ",Y2) -> Ronde 1 | AA2: Ronde 1 | AB2: =VLOOKUP(AB15,Deelnemers!A:D,2,FALSE()) -> 0 | AC2: =VLOOKUP(AC15,Deelnemers!A:D,2,FALSE()) -> 0 | AD2: =IF(AD15="","",VLOOKUP(AD15,Deelnemers!A:D,2,FALSE())) -> 0 | AE2: =IF(AE15="","",VLOOKUP(AE15,Deelnemers!A:D,2,FALSE())) -> 0 | AF2: =IF(AF15="","",VLOOKUP(AF15,Deelnemers!A:D,2,FALSE())) -> 0 | AG2: =IF(AG15="","",VLOOKUP(AG15,Deelnemers!A:D,2,FALSE())) -> 0 | AH2: =IF(AH15="","",VLOOKUP(AH15,Deelnemers!A:D,2,FALSE())) -> 0 | AI2: =IF(AI15="","",VLOOKUP(AI15,Deelnemers!A:D,2,FALSE())) -> 0
C3: Datum: | D3: =Deelnemers!$B$4 -> 2026-04-11 | H3: Setpunten per set | R3: Datum: | S3: =Deelnemers!$B$4 -> 2026-04-11 | AA3: Ronde 2 | AB3: =VLOOKUP(AB16,Deelnemers!A:D,2,FALSE()) -> 0 | AC3: =VLOOKUP(AC16,Deelnemers!A:D,2,FALSE()) -> 0 | AD3: =IF(AD16="","",VLOOKUP(AD16,Deelnemers!A:D,2,FALSE())) -> 0 | AE3: =IF(AE16="","",VLOOKUP(AE16,Deelnemers!A:D,2,FALSE())) -> 0 | AF3: =IF(AF16="","",VLOOKUP(AF16,Deelnemers!A:D,2,FALSE())) -> 0 | AG3: =IF(AG16="","",VLOOKUP(AG16,Deelnemers!A:D,2,FALSE())) -> 0 | AH3: =IF(AH16="","",VLOOKUP(AH16,Deelnemers!A:D,2,FALSE())) -> 0 | AI3: =IF(AI16="","",VLOOKUP(AI16,Deelnemers!A:D,2,FALSE())) -> 0
C4: =Deelnemers!$B$3 -> Willem Tell 1921, Kerkrade | H4: Winst:2 ;Gelijk:1 ;Verlies:0 | R4: =Deelnemers!$B$3 -> Willem Tell 1921, Kerkrade | AA4: Ronde 3 | AB4: =VLOOKUP(AB17,Deelnemers!A:D,2,FALSE()) -> 0 | AC4: =VLOOKUP(AC17,Deelnemers!A:D,2,FALSE()) -> 0 | AD4: =IF(AD17="","",VLOOKUP(AD17,Deelnemers!A:D,2,FALSE())) -> 0 | AE4: =IF(AE17="","",VLOOKUP(AE17,Deelnemers!A:D,2,FALSE())) -> 0 | AF4: =IF(AF17="","",VLOOKUP(AF17,Deelnemers!A:D,2,FALSE())) -> 0 | AG4: =IF(AG17="","",VLOOKUP(AG17,Deelnemers!A:D,2,FALSE())) -> 0 | AH4: =IF(AH17="","",VLOOKUP(AH17,Deelnemers!A:D,2,FALSE())) -> 0 | AI4: =IF(AI17="","",VLOOKUP(AI17,Deelnemers!A:D,2,FALSE())) -> 0
A5: Naam: | C5: =VLOOKUP(Z2,AA2:AI8,2,FALSE()) -> 0 | J5: Setpunten | P5: Naam: | R5: =VLOOKUP(Z2,AA2:AI8,3,FALSE()) -> 0 | AA5: Ronde 4 | AB5: =VLOOKUP(AB18,Deelnemers!A:D,2,FALSE()) -> 0 | AC5: =VLOOKUP(AC18,Deelnemers!A:D,2,FALSE()) -> 0 | AD5: =IF(AD18="","",VLOOKUP(AD18,Deelnemers!A:D,2,FALSE())) -> 0 | AE5: =IF(AE18="","",VLOOKUP(AE18,Deelnemers!A:D,2,FALSE())) -> 0 | AF5: =IF(AF18="","",VLOOKUP(AF18,Deelnemers!A:D,2,FALSE())) -> 0 | AG5: =IF(AG18="","",VLOOKUP(AG18,Deelnemers!A:D,2,FALSE())) -> 0 | AH5: =IF(AH18="","",VLOOKUP(AH18,Deelnemers!A:D,2,FALSE())) -> 0 | AI5: =IF(AI18="","",VLOOKUP(AI18,Deelnemers!A:D,2,FALSE())) -> 0
A6: nr | B6: =IF(C5="","",VLOOKUP(C5,Deelnemers!B8:C46,2,FALSE())) -> #N/A | E6: Sub | F6: Totaal | J6: Punten | L6: Punten | P6: nr | Q6: =IF(R5="","",VLOOKUP(R5,Deelnemers!B8:C46,2,FALSE())) -> #N/A | T6: Sub | U6: Totaal | AA6: Ronde 5 | AB6: =IF(AB19="","",VLOOKUP(AB19,Deelnemers!A:D,2,FALSE())) -> 0 | AC6: =IF(AC19="","",VLOOKUP(AC19,Deelnemers!A:D,2,FALSE())) -> 0 | AD6: =IF(AD19="","",VLOOKUP(AD19,Deelnemers!A:D,2,FALSE())) -> 0 | AE6: =IF(AE19="","",VLOOKUP(AE19,Deelnemers!A:D,2,FALSE())) -> 0 | AF6: =IF(AF19="","",VLOOKUP(AF19,Deelnemers!A:D,2,FALSE())) -> 0 | AG6: =IF(AG19="","",VLOOKUP(AG19,Deelnemers!A:D,2,FALSE())) -> 0 | AH6: =IF(AH19="","",VLOOKUP(AH19,Deelnemers!A:D,2,FALSE())) -> 0 | AI6: =IF(AI19="","",VLOOKUP(AI19,Deelnemers!A:D,2,FALSE())) -> 0
A7: 1 | P7: 1 | AA7: Ronde 6 | AB7: =IF(AB20="","",VLOOKUP(AB20,Deelnemers!A:D,2,FALSE())) -> 0 | AC7: =IF(AC20="","",VLOOKUP(AC20,Deelnemers!A:D,2,FALSE())) -> 0 | AD7: =IF(AD20="","",VLOOKUP(AD20,Deelnemers!A:D,2,FALSE())) -> 0 | AE7: =IF(AE20="","",VLOOKUP(AE20,Deelnemers!A:D,2,FALSE())) -> 0 | AF7: =IF(AF20="","",VLOOKUP(AF20,Deelnemers!A:D,2,FALSE())) -> 0 | AG7: =IF(AG20="","",VLOOKUP(AG20,Deelnemers!A:D,2,FALSE())) -> 0 | AH7: =IF(AH20="","",VLOOKUP(AH20,Deelnemers!A:D,2,FALSE())) -> 0 | AI7: =IF(AI20="","",VLOOKUP(AI20,Deelnemers!A:D,2,FALSE())) -> 0
AA8: Ronde 7 | AB8: =IF(AB21="","",VLOOKUP(AB21,Deelnemers!A:D,2,FALSE())) -> 0 | AC8: =IF(AC21="","",VLOOKUP(AC21,Deelnemers!A:D,2,FALSE())) -> 0 | AD8: =IF(AD21="","",VLOOKUP(AD21,Deelnemers!A:D,2,FALSE())) -> 0 | AE8: =IF(AE21="","",VLOOKUP(AE21,Deelnemers!A:D,2,FALSE())) -> 0 | AF8: =IF(AF21="","",VLOOKUP(AF21,Deelnemers!A:D,2,FALSE())) -> 0 | AG8: =IF(AG21="","",VLOOKUP(AG21,Deelnemers!A:D,2,FALSE())) -> 0 | AH8: =IF(AH21="","",VLOOKUP(AH21,Deelnemers!A:D,2,FALSE())) -> 0 | AI8: =IF(AI21="","",VLOOKUP(AI21,Deelnemers!A:D,2,FALSE())) -> 0
A9: 2 | P9: 2
A11: 3 | P11: 3
A13: 4 | P13: 4
A15: 5 | P15: 5 | AA15: Ronde 1 | AB15: =Wedstrijdschema!L3 -> Baan 1 | AC15: =Wedstrijdschema!M3 -> Baan 2 | AD15: =Wedstrijdschema!N3 -> Baan 3 | AE15: =Wedstrijdschema!O3 -> Baan 4 | AF15: =Wedstrijdschema!P3 -> Baan 5 | AG15: =Wedstrijdschema!Q3 -> Baan 6 | AH15: =Wedstrijdschema!R3 -> Baan 7 | AI15: =Wedstrijdschema!S3 -> Baan 8
AA16: Ronde 2 | AB16: =Wedstrijdschema!L4 -> Baan 1 | AC16: =Wedstrijdschema!M4 -> Baan 3 | AD16: =Wedstrijdschema!N4 -> Baan 2 | AE16: =Wedstrijdschema!O4 -> Baan 5 | AF16: =Wedstrijdschema!P4 -> Baan 4 | AG16: =Wedstrijdschema!Q4 -> Baan 7 | AH16: =Wedstrijdschema!R4 -> Baan 6 | AI16: =Wedstrijdschema!S4 -> Baan 8
D17: Totaal | S17: Totaal | AA17: Ronde 3 | AB17: =Wedstrijdschema!L5 -> Baan 1 | AC17: =Wedstrijdschema!M5 -> Baan 4 | AD17: =Wedstrijdschema!N5 -> Baan 2 | AE17: =Wedstrijdschema!O5 -> Baan 6 | AF17: =Wedstrijdschema!P5 -> Baan 3 | AG17: =Wedstrijdschema!Q5 -> Baan 8 | AH17: =Wedstrijdschema!R5 -> Baan 5 | AI17: =Wedstrijdschema!S5 -> Baan 7
A18: Deelnemer | P18: Deelnemer | AA18: Ronde 4 | AB18: =Wedstrijdschema!L6 -> Baan 1 | AC18: =Wedstrijdschema!M6 -> Baan 5 | AD18: =Wedstrijdschema!N6 -> Baan 2 | AE18: =Wedstrijdschema!O6 -> Baan 8 | AF18: =Wedstrijdschema!P6 -> Baan 3 | AG18: =Wedstrijdschema!Q6 -> Baan 7 | AH18: =Wedstrijdschema!R6 -> Baan 4 | AI18: =Wedstrijdschema!S6 -> Baan 6
A19: Handtekening | H19: Martchpunten | P19: Handtekening | AA19: Ronde 5 | AB19: =Wedstrijdschema!L7 -> Baan 1 | AC19: =Wedstrijdschema!M7 -> Baan 6 | AD19: =Wedstrijdschema!N7 -> Baan 2 | AE19: =Wedstrijdschema!O7 -> Baan 7 | AF19: =Wedstrijdschema!P7 -> Baan 3 | AG19: =Wedstrijdschema!Q7 -> Baan 5 | AH19: =Wedstrijdschema!R7 -> Baan 4 | AI19: =Wedstrijdschema!S7 -> Baan 8
A20: Controle | H20: Winst:2 ;Gelijk:1 ;Verlies:0 | P20: Controle | AA20: Ronde 6 | AB20: =Wedstrijdschema!L8 -> Baan 1 | AC20: =Wedstrijdschema!M8 -> Baan 7 | AD20: =Wedstrijdschema!N8 -> Baan 2 | AE20: =Wedstrijdschema!O8 -> Baan 4 | AF20: =Wedstrijdschema!P8 -> Baan 3 | AG20: =Wedstrijdschema!Q8 -> Baan 6 | AH20: =Wedstrijdschema!R8 -> Baan 5 | AI20: =Wedstrijdschema!S8 -> Baan 8
A21: Handtekening | P21: Handtekening | AA21: Ronde 7 | AB21: =Wedstrijdschema!L9 -> Baan 1 | AC21: =Wedstrijdschema!M9 -> Baan 8 | AD21: =Wedstrijdschema!N9 -> Baan 2 | AE21: =Wedstrijdschema!O9 -> Baan 3 | AF21: =Wedstrijdschema!P9 -> Baan 4 | AG21: =Wedstrijdschema!Q9 -> Baan 5 | AH21: =Wedstrijdschema!R9 -> Baan 6 | AI21: =Wedstrijdschema!S9 -> Baan 7
J23: Winnaar
C26: =VLOOKUP(Z2,AA14:AI21,4,FALSE()) -> Baan 3 | I26: =Z2 -> Ronde 1 | R26: =VLOOKUP(Z2,AA14:AI21,5,FALSE()) -> Baan 4
C27: Datum: | D27: =Deelnemers!$B$4 -> 2026-04-11 | H27: Setpunten per set | R27: Datum: | S27: =Deelnemers!$B$4 -> 2026-04-11
C28: =Deelnemers!$B$3 -> Willem Tell 1921, Kerkrade | H28: Winst:2 ;Gelijk:1 ;Verlies:0 | R28: =Deelnemers!$B$3 -> Willem Tell 1921, Kerkrade
A29: Naam: | C29: =VLOOKUP(Z2,AA2:AI8,4,FALSE()) -> 0 | J29: Setpunten | P29: Naam: | R29: =VLOOKUP(Z2,AA2:AI8,5,FALSE()) -> 0
A30: nr | B30: =IF(C29="","",VLOOKUP(C29,Deelnemers!B8:C46,2,FALSE())) -> #N/A | E30: Sub | F30: Totaal | J30: Punten | L30: Punten | P30: nr | Q30: =IF(R29="","",VLOOKUP(R29,Deelnemers!B8:C46,2,FALSE())) -> #N/A | T30: Sub | U30: Totaal
A31: 1 | P31: 1
A33: 2 | P33: 2
A35: 3 | P35: 3
A37: 4 | P37: 4
A39: 5 | P39: 5
D41: Totaal | S41: Totaal
A42: Deelnemer | P42: Deelnemer
A43: Handtekening | H43: Martchpunten | P43: Handtekening
A44: Controle | H44: Winst:2 ;Gelijk:1 ;Verlies:0 | P44: Controle
A45: Handtekening | P45: Handtekening
J47: Winnaar
C50: =VLOOKUP(Z2,AA14:AI21,6,FALSE()) -> Baan 5 | I50: =Z2 -> Ronde 1 | R50: =VLOOKUP(Z2,AA14:AI21,7,FALSE()) -> Baan 6
C51: Datum: | D51: =Deelnemers!$B$4 -> 2026-04-11 | H51: Setpunten per set | R51: Datum: | S51: =Deelnemers!$B$4 -> 2026-04-11
C52: =Deelnemers!$B$3 -> Willem Tell 1921, Kerkrade | H52: Winst:2 ;Gelijk:1 ;Verlies:0 | R52: =Deelnemers!$B$3 -> Willem Tell 1921, Kerkrade
A53: Naam: | C53: =VLOOKUP(Z2,AA2:AI8,6,FALSE()) -> 0 | J53: Setpunten | P53: Naam: | R53: =VLOOKUP(Z2,AA2:AI8,7,FALSE()) -> 0
A54: nr | B54: =IF(C53="","",VLOOKUP(C53,Deelnemers!B8:C46,2,FALSE())) -> #N/A | E54: Sub | F54: Totaal | J54: Punten | L54: Punten | P54: nr | Q54: =IF(R53="","",VLOOKUP(R53,Deelnemers!B8:C46,2,FALSE())) -> #N/A | T54: Sub | U54: Totaal
A55: 1 | P55: 1
...

Sheet Score briefjes 25M1P
C2: =VLOOKUP(Z2,AA11:AI18,2,FALSE()) -> Baan 1 | I2: =Z2 -> Ronde 1 | R2: =VLOOKUP(Z2,AA11:AI18,3,FALSE()) -> Baan 2 | X2: Welke ronde? | Y2: 1 | Z2: =CONCATENATE("Ronde"," ",Y2) -> Ronde 1 | AA2: Ronde 1 | AB2: =VLOOKUP(AB11,Deelnemers!A:D,2,FALSE()) -> 0 | AC2: =VLOOKUP(AC11,Deelnemers!A:D,2,FALSE()) -> 0 | AD2: =IF(AD11="","",VLOOKUP(AD11,Deelnemers!A:D,2,FALSE())) -> 0 | AE2: =IF(AE11="","",VLOOKUP(AE11,Deelnemers!A:D,2,FALSE())) -> 0 | AF2: =IF(AF11="","",VLOOKUP(AF11,Deelnemers!A:D,2,FALSE())) -> 0 | AG2: =IF(AG11="","",VLOOKUP(AG11,Deelnemers!A:D,2,FALSE())) -> 0 | AH2: =IF(AH11="","",VLOOKUP(AH11,Deelnemers!A:D,2,FALSE())) -> 0 | AI2: =IF(AI11="","",VLOOKUP(AI11,Deelnemers!A:D,2,FALSE())) -> 0
C3: Datum: | D3: =Deelnemers!$B$4 -> 2026-04-11 | H3: Setpunten per set | R3: Datum: | S3: =Deelnemers!$B$4 -> 2026-04-11 | AA3: Ronde 2 | AB3: =VLOOKUP(AB12,Deelnemers!A:D,2,FALSE()) -> 0 | AC3: =VLOOKUP(AC12,Deelnemers!A:D,2,FALSE()) -> 0 | AD3: =IF(AD12="","",VLOOKUP(AD12,Deelnemers!A:D,2,FALSE())) -> 0 | AE3: =IF(AE12="","",VLOOKUP(AE12,Deelnemers!A:D,2,FALSE())) -> 0 | AF3: =IF(AF12="","",VLOOKUP(AF12,Deelnemers!A:D,2,FALSE())) -> 0 | AG3: =IF(AG12="","",VLOOKUP(AG12,Deelnemers!A:D,2,FALSE())) -> 0 | AH3: =IF(AH12="","",VLOOKUP(AH12,Deelnemers!A:D,2,FALSE())) -> 0 | AI3: =IF(AI12="","",VLOOKUP(AI12,Deelnemers!A:D,2,FALSE())) -> 0
C4: Naam organisator, Plaats | H4: Winst:2 ;Gelijk:1 ;Verlies:0 | R4: Naam organisator, Plaats | AA4: Ronde 3 | AB4: =VLOOKUP(AB13,Deelnemers!A:D,2,FALSE()) -> 0 | AC4: =VLOOKUP(AC13,Deelnemers!A:D,2,FALSE()) -> 0 | AD4: =IF(AD13="","",VLOOKUP(AD13,Deelnemers!A:D,2,FALSE())) -> 0 | AE4: =IF(AE13="","",VLOOKUP(AE13,Deelnemers!A:D,2,FALSE())) -> 0 | AF4: =IF(AF13="","",VLOOKUP(AF13,Deelnemers!A:D,2,FALSE())) -> 0 | AG4: =IF(AG13="","",VLOOKUP(AG13,Deelnemers!A:D,2,FALSE())) -> 0 | AH4: =IF(AH13="","",VLOOKUP(AH13,Deelnemers!A:D,2,FALSE())) -> 0 | AI4: =IF(AI13="","",VLOOKUP(AI13,Deelnemers!A:D,2,FALSE())) -> 0
A5: Naam: | B5: =VLOOKUP(Z2,AA2:AI8,2,FALSE()) -> 0 | J5: Setpunten | P5: Naam: | Q5: =VLOOKUP(Z2,AA2:AI8,3,FALSE()) -> 0 | AA5: Ronde 4 | AB5: =VLOOKUP(AB14,Deelnemers!A:D,2,FALSE()) -> 0 | AC5: =VLOOKUP(AC14,Deelnemers!A:D,2,FALSE()) -> 0 | AD5: =IF(AD14="","",VLOOKUP(AD14,Deelnemers!A:D,2,FALSE())) -> 0 | AE5: =IF(AE14="","",VLOOKUP(AE14,Deelnemers!A:D,2,FALSE())) -> 0 | AF5: =IF(AF14="","",VLOOKUP(AF14,Deelnemers!A:D,2,FALSE())) -> 0 | AG5: =IF(AG14="","",VLOOKUP(AG14,Deelnemers!A:D,2,FALSE())) -> 0 | AH5: =IF(AH14="","",VLOOKUP(AH14,Deelnemers!A:D,2,FALSE())) -> 0 | AI5: =IF(AI14="","",VLOOKUP(AI14,Deelnemers!A:D,2,FALSE())) -> 0
A6: nr | B6: =IF(B5="","",VLOOKUP(B5,Deelnemers!B8:C46,2,FALSE())) -> #N/A | E6: Sub | F6: Totaal | J6: Punten | L6: Punten | P6: nr | Q6: =IF(Q5="","",VLOOKUP(Q5,Deelnemers!B8:C46,2,FALSE())) -> #N/A | T6: Sub | U6: Totaal | AA6: Ronde 5 | AB6: =IF(AB15="","",VLOOKUP(AB15,Deelnemers!A:D,2,FALSE())) -> 0 | AC6: =IF(AC15="","",VLOOKUP(AC15,Deelnemers!A:D,2,FALSE())) -> 0 | AD6: =IF(AD15="","",VLOOKUP(AD15,Deelnemers!A:D,2,FALSE())) -> 0 | AE6: =IF(AE15="","",VLOOKUP(AE15,Deelnemers!A:D,2,FALSE())) -> 0 | AF6: =IF(AF15="","",VLOOKUP(AF15,Deelnemers!A:D,2,FALSE())) -> 0 | AG6: =IF(AG15="","",VLOOKUP(AG15,Deelnemers!A:D,2,FALSE())) -> 0 | AH6: =IF(AH15="","",VLOOKUP(AH15,Deelnemers!A:D,2,FALSE())) -> 0 | AI6: =IF(AI15="","",VLOOKUP(AI15,Deelnemers!A:D,2,FALSE())) -> 0
A7: 1 | P7: 1 | AA7: Ronde 6 | AB7: =IF(AB16="","",VLOOKUP(AB16,Deelnemers!A:D,2,FALSE())) -> 0 | AC7: =IF(AC16="","",VLOOKUP(AC16,Deelnemers!A:D,2,FALSE())) -> 0 | AD7: =IF(AD16="","",VLOOKUP(AD16,Deelnemers!A:D,2,FALSE())) -> 0 | AE7: =IF(AE16="","",VLOOKUP(AE16,Deelnemers!A:D,2,FALSE())) -> 0 | AF7: =IF(AF16="","",VLOOKUP(AF16,Deelnemers!A:D,2,FALSE())) -> 0 | AG7: =IF(AG16="","",VLOOKUP(AG16,Deelnemers!A:D,2,FALSE())) -> 0 | AH7: =IF(AH16="","",VLOOKUP(AH16,Deelnemers!A:D,2,FALSE())) -> 0 | AI7: =IF(AI16="","",VLOOKUP(AI16,Deelnemers!A:D,2,FALSE())) -> 0
A8: 2 | P8: 2 | AA8: Ronde 7 | AB8: =IF(AB17="","",VLOOKUP(AB17,Deelnemers!A:D,2,FALSE())) -> 0 | AC8: =IF(AC17="","",VLOOKUP(AC17,Deelnemers!A:D,2,FALSE())) -> 0 | AD8: =IF(AD17="","",VLOOKUP(AD17,Deelnemers!A:D,2,FALSE())) -> 0 | AE8: =IF(AE17="","",VLOOKUP(AE17,Deelnemers!A:D,2,FALSE())) -> 0 | AF8: =IF(AF17="","",VLOOKUP(AF17,Deelnemers!A:D,2,FALSE())) -> 0 | AG8: =IF(AG17="","",VLOOKUP(AG17,Deelnemers!A:D,2,FALSE())) -> 0 | AH8: =IF(AH17="","",VLOOKUP(AH17,Deelnemers!A:D,2,FALSE())) -> 0 | AI8: =IF(AI17="","",VLOOKUP(AI17,Deelnemers!A:D,2,FALSE())) -> 0
A9: 3 | P9: 3
A10: 4 | P10: 4
A11: 5 | P11: 5 | AA11: Ronde 1 | AB11: =Wedstrijdschema!L3 -> Baan 1 | AC11: =Wedstrijdschema!M3 -> Baan 2 | AD11: =Wedstrijdschema!N3 -> Baan 3 | AE11: =Wedstrijdschema!O3 -> Baan 4 | AF11: =Wedstrijdschema!P3 -> Baan 5 | AG11: =Wedstrijdschema!Q3 -> Baan 6 | AH11: =Wedstrijdschema!R3 -> Baan 7 | AI11: =Wedstrijdschema!S3 -> Baan 8
D12: Totaal | S12: Totaal | AA12: Ronde 2 | AB12: =Wedstrijdschema!L4 -> Baan 1 | AC12: =Wedstrijdschema!M4 -> Baan 3 | AD12: =Wedstrijdschema!N4 -> Baan 2 | AE12: =Wedstrijdschema!O4 -> Baan 5 | AF12: =Wedstrijdschema!P4 -> Baan 4 | AG12: =Wedstrijdschema!Q4 -> Baan 7 | AH12: =Wedstrijdschema!R4 -> Baan 6 | AI12: =Wedstrijdschema!S4 -> Baan 8
A13: Deelnemer | P13: Deelnemer | AA13: Ronde 3 | AB13: =Wedstrijdschema!L5 -> Baan 1 | AC13: =Wedstrijdschema!M5 -> Baan 4 | AD13: =Wedstrijdschema!N5 -> Baan 2 | AE13: =Wedstrijdschema!O5 -> Baan 6 | AF13: =Wedstrijdschema!P5 -> Baan 3 | AG13: =Wedstrijdschema!Q5 -> Baan 8 | AH13: =Wedstrijdschema!R5 -> Baan 5 | AI13: =Wedstrijdschema!S5 -> Baan 7
A14: Handtekening | H14: Martchpunten | P14: Handtekening | AA14: Ronde 4 | AB14: =Wedstrijdschema!L6 -> Baan 1 | AC14: =Wedstrijdschema!M6 -> Baan 5 | AD14: =Wedstrijdschema!N6 -> Baan 2 | AE14: =Wedstrijdschema!O6 -> Baan 8 | AF14: =Wedstrijdschema!P6 -> Baan 3 | AG14: =Wedstrijdschema!Q6 -> Baan 7 | AH14: =Wedstrijdschema!R6 -> Baan 4 | AI14: =Wedstrijdschema!S6 -> Baan 6
A15: Controle | H15: Winst:2 ;Gelijk:1 ;Verlies:0 | P15: Controle | AA15: Ronde 5 | AB15: =Wedstrijdschema!L7 -> Baan 1 | AC15: =Wedstrijdschema!M7 -> Baan 6 | AD15: =Wedstrijdschema!N7 -> Baan 2 | AE15: =Wedstrijdschema!O7 -> Baan 7 | AF15: =Wedstrijdschema!P7 -> Baan 3 | AG15: =Wedstrijdschema!Q7 -> Baan 5 | AH15: =Wedstrijdschema!R7 -> Baan 4 | AI15: =Wedstrijdschema!S7 -> Baan 8
A16: Handtekening | P16: Handtekening | AA16: Ronde 6 | AB16: =Wedstrijdschema!L8 -> Baan 1 | AC16: =Wedstrijdschema!M8 -> Baan 7 | AD16: =Wedstrijdschema!N8 -> Baan 2 | AE16: =Wedstrijdschema!O8 -> Baan 4 | AF16: =Wedstrijdschema!P8 -> Baan 3 | AG16: =Wedstrijdschema!Q8 -> Baan 6 | AH16: =Wedstrijdschema!R8 -> Baan 5 | AI16: =Wedstrijdschema!S8 -> Baan 8
AA17: Ronde 7 | AB17: =Wedstrijdschema!L9 -> Baan 1 | AC17: =Wedstrijdschema!M9 -> Baan 8 | AD17: =Wedstrijdschema!N9 -> Baan 2 | AE17: =Wedstrijdschema!O9 -> Baan 3 | AF17: =Wedstrijdschema!P9 -> Baan 4 | AG17: =Wedstrijdschema!Q9 -> Baan 5 | AH17: =Wedstrijdschema!R9 -> Baan 6 | AI17: =Wedstrijdschema!S9 -> Baan 7
J18: Winnaar
C26: =VLOOKUP(Z2,AA11:AI18,4,FALSE()) -> Baan 3 | I26: =Z2 -> Ronde 1 | R26: =VLOOKUP(Z2,AA11:AI18,5,FALSE()) -> Baan 4
C27: Datum: | D27: =Deelnemers!$B$4 -> 2026-04-11 | H27: Setpunten per set | R27: Datum: | S27: =Deelnemers!$B$4 -> 2026-04-11
C28: =Deelnemers!$B$3 -> Willem Tell 1921, Kerkrade | H28: Winst:2 ;Gelijk:1 ;Verlies:0 | R28: =Deelnemers!$B$3 -> Willem Tell 1921, Kerkrade
A29: Naam: | B29: =VLOOKUP(Z2,AA2:AI8,4,FALSE()) -> 0 | J29: Setpunten | P29: Naam: | Q29: =VLOOKUP(Z2,AA2:AI8,5,FALSE()) -> 0
A30: nr | B30: =IF(B29="","",VLOOKUP(B29,Deelnemers!B8:C46,2,FALSE())) -> #N/A | E30: Sub | F30: Totaal | J30: Punten | L30: Punten | P30: nr | Q30: =IF(Q29="","",VLOOKUP(Q29,Deelnemers!B8:C46,2,FALSE())) -> #N/A | T30: Sub | U30: Totaal
A31: 1 | P31: 1
A32: 2 | P32: 2
A33: 3 | P33: 3
A34: 4 | P34: 4
A35: 5 | P35: 5
D36: Totaal | S36: Totaal
A37: Deelnemer | P37: Deelnemer
A38: Handtekening | H38: Martchpunten | P38: Handtekening
A39: Controle | H39: Winst:2 ;Gelijk:1 ;Verlies:0 | P39: Controle
A40: Handtekening | P40: Handtekening
J42: Winnaar
C45: =VLOOKUP(Z2,AA11:AI18,6,FALSE()) -> Baan 5 | I45: =Z2 -> Ronde 1 | R45: =VLOOKUP(Z2,AA11:AI18,7,FALSE()) -> Baan 6
C46: Datum: | D46: =Deelnemers!$B$4 -> 2026-04-11 | H46: Setpunten per set | R46: Datum: | S46: =Deelnemers!$B$4 -> 2026-04-11
C47: =Deelnemers!$B$3 -> Willem Tell 1921, Kerkrade | H47: Winst:2 ;Gelijk:1 ;Verlies:0 | R47: =Deelnemers!$B$3 -> Willem Tell 1921, Kerkrade
A48: Naam: | B48: =VLOOKUP(Z2,AA2:AI8,6,FALSE()) -> 0 | J48: Setpunten | P48: Naam: | Q48: =VLOOKUP(Z2,AA2:AI8,7,FALSE()) -> 0
A49: nr | B49: =IF(B48="","",VLOOKUP(B48,Deelnemers!B8:C46,2,FALSE())) -> #N/A | E49: Sub | F49: Totaal | J49: Punten | L49: Punten | P49: nr | Q49: =IF(Q48="","",VLOOKUP(Q48,Deelnemers!B8:C46,2,FALSE())) -> #N/A | T49: Sub | U49: Totaal
A50: 1 | P50: 1
A51: 2 | P51: 2
...

Sheet Naambriefje
A1: =Deelnemers!$B$1 -> RK Teams Rayon 4, 25m 1pijl competitie 2025/2026
A2: =Deelnemers!$B$2 -> Recurve klasse D
A3: =_xlfn.TEXTJOIN(", ",TRUE(),Deelnemers!B3,Deelnemers!B4) -> Willem Tell 1921, Kerkrade, 2026-04-11
E5: Voor printen:
A6: =VLOOKUP(C6,Deelnemers!A8:C46,3,FALSE()) -> 0 | B6: =VLOOKUP(C6,Deelnemers!A8:C46,2,FALSE()) -> 0 | C6: Baan 1 | E6: Selecteer eerst het juiste baannummer | J6: =Deelnemers!A8 -> Baan 1 | K6: =Deelnemers!A13 -> Baan 2
J7: =Deelnemers!A18 -> Baan 3 | K7: =Deelnemers!A23 -> Baan 4
A8: Bondsnr. | B8: Naam | J8: =Deelnemers!A28 -> Baan 5 | K8: =Deelnemers!A33 -> Baan 6
C9: Schutter 1 | J9: =Deelnemers!A38 -> Baan 7 | K9: =Deelnemers!A43 -> Baan 8
C10: Schutter 2
C11: Schutter 3
A18: =Deelnemers!$B$1 -> RK Teams Rayon 4, 25m 1pijl competitie 2025/2026
A19: =Deelnemers!$B$2 -> Recurve klasse D
A20: =_xlfn.TEXTJOIN(", ",TRUE(),Deelnemers!B3,Deelnemers!B4) -> Willem Tell 1921, Kerkrade, 2026-04-11
A23: =VLOOKUP(C6,Deelnemers!A8:C46,3,FALSE()) -> 0 | B23: =VLOOKUP(C23,Deelnemers!A8:C46,2,FALSE()) -> 0 | C23: =VLOOKUP(C6,J6:K9,2,FALSE()) -> Baan 2
A25: Bondsnr. | B25: Naam
C26: Schutter 1
C27: Schutter 2
C28: Schutter 3
